---
description: 詳細については、' Throw ' ステートメントは、' Catch ' ステートメントの外側、または ' Finally ' ステートメントの内側にあるオペランドを省略することはできません。
title: "'Throw' ステートメントでは、'Catch' ステートメントの外側、または 'Finally' ステートメントの内側にあるオペランドを省略できません"
ms.date: 07/20/2015
f1_keywords:
- vbc30666
- bc30666
helpviewer_keywords:
- BC30666
ms.assetid: a208a6ea-0e36-4bf1-8984-4de1a0e38a2a
ms.openlocfilehash: 8ab76ae9e5727388ddb77ec38f1b4e89b6a0e5d6
ms.sourcegitcommit: 10e719780594efc781b15295e499c66f316068b8
ms.translationtype: MT
ms.contentlocale: ja-JP
ms.lasthandoff: 02/14/2021
ms.locfileid: "100460840"
---
# <a name="throw-statement-cannot-omit-operand-outside-a-catch-statement-or-inside-a-finally-statement"></a>'Throw' ステートメントでは、'Catch' ステートメントの外側、または 'Finally' ステートメントの内側にあるオペランドを省略できません

`Throw` ステートメントの外側にある `Catch` ステートメントでは、例外オブジェクトの名前を指定する必要があります。  
  
 **エラー ID:** BC30666  
  
## <a name="to-correct-this-error"></a>このエラーを解決するには  
  
1. `System.Exception`から派生した例外オブジェクトの名前を指定します。  
  
2. `Throw` ステートメントが `Catch` ブロックの内側に配置されるようにコードを再構築します。  
  
## <a name="see-also"></a>関連項目

- [Throw ステートメント](../language-reference/statements/throw-statement.md)
- [Try...Catch...Finally ステートメント](../language-reference/statements/try-catch-finally-statement.md)
- <xref:System.Exception?displayProperty=nameWithType>
- [.NET での例外の処理とスロー](../../standard/exceptions/index.md)
